<?xml version='1.0' encoding='utf-8'?>
<robot name="galbot_one_golf">
  <link name="base_link">
    </link>
  <joint name="omni_chassis_joint" type="fixed">
    <origin rpy="0 0 0" xyz="0 0 0" />
    <parent link="base_link" />
    <child link="omni_chassis_base_link" />
  </joint>
  <link name="omni_chassis_base_link">
    <inertial>
      <origin rpy="0 0 0" xyz="0.02644 -0.00449 0.07524" />
      <mass value="8.04" />
      <inertia ixx="0.19508898000000002" ixy="0.00306854" ixz="0.01503967" iyy="0.29573702" iyz="-0.00295148" izz="0.3313144" />
    </inertial>
    <visual>
      <origin rpy="0 0 0" xyz="0 0 0" />
      <geometry>
        <mesh filename="assets/embodiments/galbot-one-golf/urdf/meshes/visual/chassis/omni_chassis_base_link/obj/omni_chassis_base_link.obj" />
      </geometry>
    </visual>
  </link>
  <link name="omni_chassis_leg_mount_link">
    <inertial>
      <origin rpy="0 0 0" xyz="0 0 0" />
      <mass value="0" />
      <inertia ixx="0" ixy="0" ixz="0" iyy="0" iyz="0" izz="0" />
    </inertial>
  </link>
  <joint name="omni_chassis_leg_mount_joint" type="fixed">
    <origin rpy="0 0 0" xyz="0.134 0 0.1325" />
    <parent link="omni_chassis_base_link" />
    <child link="omni_chassis_leg_mount_link" />
    <axis xyz="0 0 0" />
  </joint>
  <joint name="leg_joint" type="fixed">
    <origin rpy="0 0 0" xyz="0 0 0" />
    <parent link="omni_chassis_leg_mount_link" />
    <child link="leg_base_link" />
  </joint>
  <link name="leg_base_link">
    <inertial>
      <origin rpy="0 0 0" xyz="7.000000000000001e-05 -0.05414 0.0" />
      <mass value="1.58" />
      <inertia ixx="0.00797474" ixy="8.35e-06" ixz="2e-08" iyy="0.00248067" iyz="6.9e-07" izz="0.00797203" />
    </inertial>
  </link>
  <link name="leg_link1">
    <inertial>
      <origin rpy="0 0 0" xyz="0.21883000000000002 0.00219 -0.0046" />
      <mass value="5.28" />
      <inertia ixx="0.0245158" ixy="0.003598" ixz="-0.004119" iyy="0.46437793" iyz="2.301e-05" izz="0.46079615" />
    </inertial>
    <visual>
      <origin rpy="0 0 0" xyz="0 0 0" />
      <geometry>
        <mesh filename="assets/embodiments/galbot-one-golf/urdf/meshes/visual/leg/leg_link1/obj/leg_link1.obj" />
      </geometry>
    </visual>
  </link>
  <joint name="leg_joint1" type="fixed">
    <origin rpy="1.5707963267948966 -0.64795799999999992 3.1415926535897931" xyz="0 0 0" />
    <parent link="leg_base_link" />
    <child link="leg_link1" />
  </joint>
  <link name="leg_link2">
    <inertial>
      <origin rpy="0 0 0" xyz="0.19484 0.0 0.0" />
      <mass value="3.3" />
      <inertia ixx="0.04156241" ixy="7.2e-07" ixz="1.559e-05" iyy="0.23231617000000002" iyz="-2.7799999999999996e-06" izz="0.20323657" />
    </inertial>
    <visual>
      <origin rpy="0 0 0" xyz="0 0 0" />
      <geometry>
        <mesh filename="assets/embodiments/galbot-one-golf/urdf/meshes/visual/leg/leg_link2/obj/leg_link2.obj" />
      </geometry>
    </visual>
  </link>
  <joint name="leg_joint2" type="fixed">
    <origin rpy="3.1411668683756622 0.0015861030696706635 1.9784346182719643" xyz="0.45130567116666476 0 0" />
    <parent link="leg_link1" />
    <child link="leg_link2" />
  </joint>
  <link name="leg_link3">
    <inertial>
      <origin rpy="0 0 0" xyz="2e-05 0.01881 -0.011" />
      <mass value="1.76" />
      <inertia ixx="0.01102444" ixy="1.13e-06" ixz="-1.26e-06" iyy="0.00878281" iyz="1.26e-06" izz="0.0106222" />
    </inertial>
    <visual>
      <origin rpy="0 0 0" xyz="0 0 0" />
      <geometry>
        <mesh filename="assets/embodiments/galbot-one-golf/urdf/meshes/visual/leg/leg_link3/obj/leg_link3.obj" />
      </geometry>
    </visual>
  </link>
  <joint name="leg_joint3" type="fixed">
    <origin rpy="-3.1414053815495899 0.00022907941895611295 2.6253900019221232" xyz="0.39110937388681893 0 0" />
    <parent link="leg_link2" />
    <child link="leg_link3" />
  </joint>
  <link name="leg_link4">
    <inertial>
      <origin rpy="0 0 0" xyz="0.0 -0.0059900000000000005 -0.06877" />
      <mass value="0.72" />
      <inertia ixx="0.00580757" ixy="0.0" ixz="0.0" iyy="0.00591483" iyz="4.67e-06" izz="0.0014004900000000001" />
    </inertial>
    <visual>
      <origin rpy="0 0 0" xyz="0 0 0" />
      <geometry>
        <mesh filename="assets/embodiments/galbot-one-golf/urdf/meshes/visual/leg/leg_link4/obj/leg_link4.obj" />
      </geometry>
    </visual>
  </link>
  <joint name="leg_joint4" type="fixed">
    <origin rpy="2.3128231346453596 -1.5680546903729649 2.399567717818738" xyz="0.0015662071663960246 0.22464422633515163 -0.0004162102320351968" />
    <parent link="leg_link3" />
    <child link="leg_link4" />
  </joint>
  <link name="leg_link5">
    <inertial>
      <origin rpy="0 0 0" xyz="0.0 0.032369999999999996 0.03006" />
      <mass value="0.41" />
      <inertia ixx="0.00142201" ixy="0.0" ixz="0.0" iyy="0.00132398" iyz="0.00023940999999999999" izz="0.00156199" />
    </inertial>
    <visual>
      <origin rpy="0 0 0" xyz="0 0 0" />
      <geometry>
        <mesh filename="assets/embodiments/galbot-one-golf/urdf/meshes/visual/leg/leg_link5/obj/leg_link5.obj" />
      </geometry>
    </visual>
  </link>
  <joint name="leg_joint5" type="fixed">
    <origin rpy="1.5707963267948966 3.5999999999924981e-05 0" xyz="0 0 0" />
    <parent link="leg_link4" />
    <child link="leg_link5" />
  </joint>
  <link name="leg_end_effector_mount_link">
    <inertial>
      <origin rpy="0 0 0" xyz="0 0 0" />
      <mass value="0" />
      <inertia ixx="0" ixy="0" ixz="0" iyy="0" iyz="0" izz="0" />
    </inertial>
  </link>
  <joint name="leg_end_effector_mount_joint" type="fixed">
    <origin rpy="0 0 0" xyz="0 0 0" />
    <parent link="leg_link5" />
    <child link="leg_end_effector_mount_link" />
    <axis xyz="0 0 0" />
  </joint>
  <joint name="torso_joint" type="fixed">
    <origin rpy="0 0 0" xyz="0 0 0" />
    <parent link="leg_end_effector_mount_link" />
    <child link="torso_base_link" />
  </joint>
  <link name="torso_base_link">
    <inertial>
      <origin rpy="0 0 0" xyz="-4e-05 0.16976 -0.00174" />
      <mass value="3.3" />
      <inertia ixx="0.13068739999999998" ixy="-3.799e-05" ixz="2.6e-07" iyy="0.01888968" iyz="-0.00210909" izz="0.13964288" />
    </inertial>
    <visual>
      <origin rpy="0 0 0" xyz="0 0 0" />
      <geometry>
        <mesh filename="assets/embodiments/galbot-one-golf/urdf/meshes/visual/torso/torso_base_link/obj/torso_base_link.obj" />
      </geometry>
    </visual>
  </link>
  <link name="torso_left_arm_mount_link">
    <inertial>
      <origin rpy="0 0 0" xyz="0 0 0" />
      <mass value="0" />
      <inertia ixx="0" ixy="0" ixz="0" iyy="0" iyz="0" izz="0" />
    </inertial>
  </link>
  <joint name="torso_left_arm_mount_joint" type="fixed">
    <origin rpy="2.063613084642995 1.5641659762210041 2.0615765275709705" xyz="0.20985087323491561 0.17348480077644576 -0.0004400370074035719" />
    <parent link="torso_base_link" />
    <child link="torso_left_arm_mount_link" />
    <axis xyz="0 0 0" />
  </joint>
  <link name="torso_right_arm_mount_link">
    <inertial>
      <origin rpy="0 0 0" xyz="0 0 0" />
      <mass value="0" />
      <inertia ixx="0" ixy="0" ixz="0" iyy="0" iyz="0" izz="0" />
    </inertial>
  </link>
  <joint name="torso_right_arm_mount_joint" type="fixed">
    <origin rpy="-1.5513206572339588 1.5632233140410912 1.5872685849237276" xyz="-0.20851765756567331 0.17387520191700401 0.00090370579607370488" />
    <parent link="torso_base_link" />
    <child link="torso_right_arm_mount_link" />
    <axis xyz="0 0 0" />
  </joint>
  <link name="torso_head_mount_link">
    <inertial>
      <origin rpy="0 0 0" xyz="0 0 0" />
      <mass value="0" />
      <inertia ixx="0" ixy="0" ixz="0" iyy="0" iyz="0" izz="0" />
    </inertial>
  </link>
  <joint name="torso_head_mount_joint" type="fixed">
    <origin rpy="1.3751887606505067 -1.5672182350569761 -2.9456012403089309" xyz="0.00067196471932258256 0.37812990684999476 0.00038409279548909159" />
    <parent link="torso_base_link" />
    <child link="torso_head_mount_link" />
    <axis xyz="0 0 0" />
  </joint>
  <joint name="head_joint" type="fixed">
    <origin rpy="0 0 0" xyz="0 0 0" />
    <parent link="torso_head_mount_link" />
    <child link="head_base_link" />
  </joint>
  <link name="head_base_link">
    <inertial>
      <origin rpy="0 0 0" xyz="0.023809999999999998 0.00032 0.01966" />
      <mass value="0.48" />
      <inertia ixx="0.0032910599999999997" ixy="8.32e-06" ixz="0.00044358" iyy="0.00375998" iyz="7.18e-06" izz="0.00221683" />
    </inertial>
  </link>
  <link name="head_link1">
    <inertial>
      <origin rpy="0 0 0" xyz="-2e-05 0.00709 -0.0559" />
      <mass value="1.5695" />
      <inertia ixx="0.0069002956" ixy="0.00000152205" ixz="0.00000313295" iyy="0.00683300359" iyz="0.00001009318" izz="0.00116967635" />
    </inertial>
    <visual>
      <origin rpy="0 0 0" xyz="0 0 0" />
      <geometry>
        <mesh filename="assets/embodiments/galbot-one-golf/urdf/meshes/visual/head/head_link1/obj/head_link1.obj" />
      </geometry>
    </visual>
  </link>
  <joint name="head_joint1" type="fixed">
    <origin rpy="0 0 -0.00039499999999999995" xyz="0 0 0" />
    <parent link="head_base_link" />
    <child link="head_link1" />
  </joint>
  <link name="head_link2">
    <inertial>
      <origin rpy="0 0 0" xyz="0.01835 -0.033479999999999996 0.00642" />
      <mass value="0.81" />
      <inertia ixx="0.00000399161" ixy="0.00000129825" ixz="0.00000000392" iyy="0.00000372602" iyz="0.00000000775" izz="0.00000553062" />
    </inertial>
    <visual>
      <origin rpy="0 0 0" xyz="0 0 0" />
      <geometry>
        <mesh filename="assets/embodiments/galbot-one-golf/urdf/meshes/visual/head/head_link2/obj/head_link2.obj" />
      </geometry>
    </visual>
  </link>
  <joint name="head_joint2" type="fixed">
    <origin rpy="-1.5671738243428721 0.41887056204249729 0.0014733818738132953" xyz="0.0018024500480104705 0 0" />
    <parent link="head_link1" />
    <child link="head_link2" />
  </joint>
  <link name="head_end_effector_mount_link">
    <inertial>
      <origin rpy="0 0 0" xyz="0 0 0" />
      <mass value="0" />
      <inertia ixx="0" ixy="0" ixz="0" iyy="0" iyz="0" izz="0" />
    </inertial>
  </link>
  <joint name="head_end_effector_mount_joint" type="fixed">
    <origin rpy="0 0 0" xyz="0 0 0" />
    <parent link="head_link2" />
    <child link="head_end_effector_mount_link" />
    <axis xyz="0 0 0" />
  </joint>
  <joint name="right_arm_joint" type="fixed">
    <origin rpy="0 0 0" xyz="0 0 0" />
    <parent link="torso_right_arm_mount_link" />
    <child link="right_arm_base_link" />
  </joint>
  <link name="right_arm_base_link">
    <inertial>
      <origin rpy="0 0 0" xyz="0.0 0.0 -0.10506" />
      <mass value="0.92" />
      <inertia ixx="0.01075595" ixy="9e-08" ixz="4.1e-07" iyy="0.01077842" iyz="1.896e-05" izz="0.0007042000000000001" />
    </inertial>
  </link>
  <link name="right_arm_link1">
    <inertial>
      <origin rpy="0 0 0" xyz="0.0 -0.0009699999999999999 -0.015390000000000001" />
      <mass value="0.128" />
      <inertia ixx="0.0002663848" ixy="1.5136e-06" ixz="5.52e-08" iyy="0.0002712968" iyz="2.3808e-06" izz="0.000132192" />
    </inertial>
    <visual>
      <origin rpy="0 0 0" xyz="0 0 0" />
      <geometry>
        <mesh filename="assets/embodiments/galbot-one-golf/urdf/meshes/visual/right_arm/right_arm_link1/obj/right_arm_link1.obj" />
      </geometry>
    </visual>
    <collision>
      <origin rpy="0 0 0" xyz="0 0 0" />
      <geometry>
        <mesh filename="assets/embodiments/galbot-one-golf/urdf/meshes/collision/right_arm/right_arm_link1/convex_decomposition/right_arm_link1_convex_decomposition_0.stl" />
      </geometry>
    </collision>
    <collision>
      <origin rpy="0 0 0" xyz="0 0 0" />
      <geometry>
        <mesh filename="assets/embodiments/galbot-one-golf/urdf/meshes/collision/right_arm/right_arm_link1/convex_decomposition/right_arm_link1_convex_decomposition_1.stl" />
      </geometry>
    </collision>
  </link>
  <joint name="right_arm_joint1" type="revolute">
    <origin rpy="0 0 -0.523598775598286" xyz="0 0 0" />
    <parent link="right_arm_base_link" />
    <child link="right_arm_link1" />
    <axis xyz="0 0 1" />
    <limit acceleration="2" effort="1000" jerk="12" lower="-3.00432619" upper="3.00432619" velocity="1000" />
  </joint>
  <link name="right_arm_link2">
    <inertial>
      <origin rpy="0 0 0" xyz="0.0 -0.09558 0.010150000000000001" />
      <mass value="0.1144" />
      <inertia ixx="0.0015503048" ixy="1.6e-08" ixz="9.6e-09" iyy="0.0001263312" iyz="1.56624e-05" izz="0.0015161448" />
    </inertial>
    <visual>
      <origin rpy="0 0 0" xyz="0 0 0" />
      <geometry>
        <mesh filename="assets/embodiments/galbot-one-golf/urdf/meshes/visual/right_arm/right_arm_link2/obj/right_arm_link2.obj" />
      </geometry>
    </visual>
    <collision>
      <origin rpy="0 0 0" xyz="0 0 0" />
      <geometry>
        <mesh filename="assets/embodiments/galbot-one-golf/urdf/meshes/collision/right_arm/right_arm_link2/convex_decomposition/right_arm_link2_convex_decomposition_0.stl" />
      </geometry>
    </collision>
    <collision>
      <origin rpy="0 0 0" xyz="0 0 0" />
      <geometry>
        <mesh filename="assets/embodiments/galbot-one-golf/urdf/meshes/collision/right_arm/right_arm_link2/convex_decomposition/right_arm_link2_convex_decomposition_1.stl" />
      </geometry>
    </collision>
    <collision>
      <origin rpy="0 0 0" xyz="0 0 0" />
      <geometry>
        <mesh filename="assets/embodiments/galbot-one-golf/urdf/meshes/collision/right_arm/right_arm_link2/convex_decomposition/right_arm_link2_convex_decomposition_2.stl" />
      </geometry>
    </collision>
    <collision>
      <origin rpy="0 0 0" xyz="0 0 0" />
      <geometry>
        <mesh filename="assets/embodiments/galbot-one-golf/urdf/meshes/collision/right_arm/right_arm_link2/convex_decomposition/right_arm_link2_convex_decomposition_3.stl" />
      </geometry>
    </collision>
    <collision>
      <origin rpy="0 0 0" xyz="0 0 0" />
      <geometry>
        <mesh filename="assets/embodiments/galbot-one-golf/urdf/meshes/collision/right_arm/right_arm_link2/convex_decomposition/right_arm_link2_convex_decomposition_4.stl" />
      </geometry>
    </collision>
  </link>
  <joint name="right_arm_joint2" type="revolute">
    <origin rpy="-1.570225877027188 -0.016969420261516488 3.1415829738514778" xyz="-1.5112387179470627e-05 0.00023825427837880547 -1.35892544253361e-07" />
    <parent link="right_arm_link1" />
    <child link="right_arm_link2" />
    <axis xyz="0 0 1" />
    <limit acceleration="2" effort="1000" jerk="12" lower="-1.608062789" upper="1.608062789" velocity="1000" />
  </joint>
  <link name="right_arm_link3">
    <inertial>
      <origin rpy="0 0 0" xyz="0.0 -0.00088 -0.04936" />
      <mass value="0.1144" />
      <inertia ixx="0.0009499656" ixy="1.2e-08" ixz="6.8e-08" iyy="0.0009430072000000001" iyz="8.038400000000001e-06" izz="0.00010972" />
    </inertial>
    <visual>
      <origin rpy="0 0 0" xyz="0 0 0" />
      <geometry>
        <mesh filename="assets/embodiments/galbot-one-golf/urdf/meshes/visual/right_arm/right_arm_link3/obj/right_arm_link3.obj" />
      </geometry>
    </visual>
    <collision>
      <origin rpy="0 0 0" xyz="0 0 0" />
      <geometry>
        <mesh filename="assets/embodiments/galbot-one-golf/urdf/meshes/collision/right_arm/right_arm_link3/convex_decomposition/right_arm_link3_convex_decomposition_0.stl" />
      </geometry>
    </collision>
    <collision>
      <origin rpy="0 0 0" xyz="0 0 0" />
      <geometry>
        <mesh filename="assets/embodiments/galbot-one-golf/urdf/meshes/collision/right_arm/right_arm_link3/convex_decomposition/right_arm_link3_convex_decomposition_1.stl" />
      </geometry>
    </collision>
    <collision>
      <origin rpy="0 0 0" xyz="0 0 0" />
      <geometry>
        <mesh filename="assets/embodiments/galbot-one-golf/urdf/meshes/collision/right_arm/right_arm_link3/convex_decomposition/right_arm_link3_convex_decomposition_2.stl" />
      </geometry>
    </collision>
    <collision>
      <origin rpy="0 0 0" xyz="0 0 0" />
      <geometry>
        <mesh filename="assets/embodiments/galbot-one-golf/urdf/meshes/collision/right_arm/right_arm_link3/convex_decomposition/right_arm_link3_convex_decomposition_3.stl" />
      </geometry>
    </collision>
    <collision>
      <origin rpy="0 0 0" xyz="0 0 0" />
      <geometry>
        <mesh filename="assets/embodiments/galbot-one-golf/urdf/meshes/collision/right_arm/right_arm_link3/convex_decomposition/right_arm_link3_convex_decomposition_4.stl" />
      </geometry>
    </collision>
    <collision>
      <origin rpy="0 0 0" xyz="0 0 0" />
      <geometry>
        <mesh filename="assets/embodiments/galbot-one-golf/urdf/meshes/collision/right_arm/right_arm_link3/convex_decomposition/right_arm_link3_convex_decomposition_5.stl" />
      </geometry>
    </collision>
    <collision>
      <origin rpy="0 0 0" xyz="0 0 0" />
      <geometry>
        <mesh filename="assets/embodiments/galbot-one-golf/urdf/meshes/collision/right_arm/right_arm_link3/convex_decomposition/right_arm_link3_convex_decomposition_6.stl" />
      </geometry>
    </collision>
    <collision>
      <origin rpy="0 0 0" xyz="0 0 0" />
      <geometry>
        <mesh filename="assets/embodiments/galbot-one-golf/urdf/meshes/collision/right_arm/right_arm_link3/convex_decomposition/right_arm_link3_convex_decomposition_7.stl" />
      </geometry>
    </collision>
    <collision>
      <origin rpy="0 0 0" xyz="0 0 0" />
      <geometry>
        <mesh filename="assets/embodiments/galbot-one-golf/urdf/meshes/collision/right_arm/right_arm_link3/convex_decomposition/right_arm_link3_convex_decomposition_8.stl" />
      </geometry>
    </collision>
  </link>
  <joint name="right_arm_joint3" type="revolute">
    <origin rpy="-1.5721416642110733 1.0459989875833773 3.1404283641072919" xyz="0.00033207429546214652 -0.35020809076740123 -0.00023606288240424211" />
    <parent link="right_arm_link2" />
    <child link="right_arm_link3" />
    <axis xyz="0 0 1" />
    <limit acceleration="2" effort="1000" jerk="12" lower="-2.916972222" upper="2.916972222" velocity="1000" />
  </joint>
  <link name="right_arm_link4">
    <inertial>
      <origin rpy="0 0 0" xyz="0.0 -0.05614 0.019170000000000003" />
      <mass value="0.08800000000000001" />
      <inertia ixx="0.0005611104" ixy="2.56e-08" ixz="9.28e-08" iyy="0.0001294832" iyz="2.71552e-05" izz="0.0005200959999999999" />
    </inertial>
    <visual>
      <origin rpy="0 0 0" xyz="0 0 0" />
      <geometry>
        <mesh filename="assets/embodiments/galbot-one-golf/urdf/meshes/visual/right_arm/right_arm_link4/obj/right_arm_link4.obj" />
      </geometry>
    </visual>
    <collision>
      <origin rpy="0 0 0" xyz="0 0 0" />
      <geometry>
        <mesh filename="assets/embodiments/galbot-one-golf/urdf/meshes/collision/right_arm/right_arm_link4/convex_decomposition/right_arm_link4_convex_decomposition_0.stl" />
      </geometry>
    </collision>
    <collision>
      <origin rpy="0 0 0" xyz="0 0 0" />
      <geometry>
        <mesh filename="assets/embodiments/galbot-one-golf/urdf/meshes/collision/right_arm/right_arm_link4/convex_decomposition/right_arm_link4_convex_decomposition_1.stl" />
      </geometry>
    </collision>
    <collision>
      <origin rpy="0 0 0" xyz="0 0 0" />
      <geometry>
        <mesh filename="assets/embodiments/galbot-one-golf/urdf/meshes/collision/right_arm/right_arm_link4/convex_decomposition/right_arm_link4_convex_decomposition_2.stl" />
      </geometry>
    </collision>
    <collision>
      <origin rpy="0 0 0" xyz="0 0 0" />
      <geometry>
        <mesh filename="assets/embodiments/galbot-one-golf/urdf/meshes/collision/right_arm/right_arm_link4/convex_decomposition/right_arm_link4_convex_decomposition_3.stl" />
      </geometry>
    </collision>
    <collision>
      <origin rpy="0 0 0" xyz="0 0 0" />
      <geometry>
        <mesh filename="assets/embodiments/galbot-one-golf/urdf/meshes/collision/right_arm/right_arm_link4/convex_decomposition/right_arm_link4_convex_decomposition_4.stl" />
      </geometry>
    </collision>
    <collision>
      <origin rpy="0 0 0" xyz="0 0 0" />
      <geometry>
        <mesh filename="assets/embodiments/galbot-one-golf/urdf/meshes/collision/right_arm/right_arm_link4/convex_decomposition/right_arm_link4_convex_decomposition_5.stl" />
      </geometry>
    </collision>
  </link>
  <joint name="right_arm_joint4" type="revolute">
    <origin rpy="-1.5695956059989917 -0.0011312171701447493 3.1415912953134493" xyz="-0.00039734393431168247 0.00012052882965165942 -1.447214492218869e-07" />
    <parent link="right_arm_link3" />
    <child link="right_arm_link4" />
    <axis xyz="0 0 1" />
    <limit acceleration="2" effort="1000" jerk="12" lower="-1.869862177" upper="2.5679938779914944" velocity="1000" />
  </joint>
  <link name="right_arm_link5">
    <inertial>
      <origin rpy="0 0 0" xyz="0.00044 0.0016899999999999999 -0.13306" />
      <mass value="0.092" />
      <inertia ixx="0.0020647944" ixy="1.584e-06" ixz="4.484e-06" iyy="0.0020242504" iyz="1.67456e-05" izz="9.26784e-05" />
    </inertial>
    <visual>
      <origin rpy="0 0 0" xyz="0 0 0" />
      <geometry>
        <mesh filename="assets/embodiments/galbot-one-golf/urdf/meshes/visual/right_arm/right_arm_link5/obj/right_arm_link5.obj" />
      </geometry>
    </visual>
    <collision>
      <origin rpy="0 0 0" xyz="0 0 0" />
      <geometry>
        <mesh filename="assets/embodiments/galbot-one-golf/urdf/meshes/collision/right_arm/right_arm_link5/convex_decomposition/right_arm_link5_convex_decomposition_0.stl" />
      </geometry>
    </collision>
    <collision>
      <origin rpy="0 0 0" xyz="0 0 0" />
      <geometry>
        <mesh filename="assets/embodiments/galbot-one-golf/urdf/meshes/collision/right_arm/right_arm_link5/convex_decomposition/right_arm_link5_convex_decomposition_1.stl" />
      </geometry>
    </collision>
    <collision>
      <origin rpy="0 0 0" xyz="0 0 0" />
      <geometry>
        <mesh filename="assets/embodiments/galbot-one-golf/urdf/meshes/collision/right_arm/right_arm_link5/convex_decomposition/right_arm_link5_convex_decomposition_2.stl" />
      </geometry>
    </collision>
  </link>
  <joint name="right_arm_joint5" type="revolute">
    <origin rpy="-1.5673527855065266 -0.0077499825271560852 3.1415659663666475" xyz="0.00025427024153545566 -0.36045373215355803 0.0012412049392862556" />
    <parent link="right_arm_link4" />
    <child link="right_arm_link5" />
    <axis xyz="0 0 1" />
    <limit acceleration="2" effort="1000" jerk="12" lower="-2.916972222" upper="2.916972222" velocity="1000" />
  </joint>
  <link name="right_arm_link6">
    <inertial>
      <origin rpy="0 0 0" xyz="-0.00088 0.0072699999999999996 -0.00011999999999999999" />
      <mass value="0.0376" />
      <inertia ixx="2.20456e-05" ixy="6.08e-08" ixz="1.152e-07" iyy="2.31824e-05" iyz="1.8e-07" izz="2.37472e-05" />
    </inertial>
    <visual>
      <origin rpy="0 0 0" xyz="0 0 0" />
      <geometry>
        <mesh filename="assets/embodiments/galbot-one-golf/urdf/meshes/visual/right_arm/right_arm_link6/obj/right_arm_link6.obj" />
      </geometry>
    </visual>
    <collision>
      <origin rpy="0 0 0" xyz="0 0 0" />
      <geometry>
        <mesh filename="assets/embodiments/galbot-one-golf/urdf/meshes/collision/right_arm/right_arm_link6/convex_decomposition/right_arm_link6_convex_decomposition_0.stl" />
      </geometry>
    </collision>
    <collision>
      <origin rpy="0 0 0" xyz="0 0 0" />
      <geometry>
        <mesh filename="assets/embodiments/galbot-one-golf/urdf/meshes/collision/right_arm/right_arm_link6/convex_decomposition/right_arm_link6_convex_decomposition_1.stl" />
      </geometry>
    </collision>
    <collision>
      <origin rpy="0 0 0" xyz="0 0 0" />
      <geometry>
        <mesh filename="assets/embodiments/galbot-one-golf/urdf/meshes/collision/right_arm/right_arm_link6/convex_decomposition/right_arm_link6_convex_decomposition_2.stl" />
      </geometry>
    </collision>
    <collision>
      <origin rpy="0 0 0" xyz="0 0 0" />
      <geometry>
        <mesh filename="assets/embodiments/galbot-one-golf/urdf/meshes/collision/right_arm/right_arm_link6/convex_decomposition/right_arm_link6_convex_decomposition_3.stl" />
      </geometry>
    </collision>
    <collision>
      <origin rpy="0 0 0" xyz="0 0 0" />
      <geometry>
        <mesh filename="assets/embodiments/galbot-one-golf/urdf/meshes/collision/right_arm/right_arm_link6/convex_decomposition/right_arm_link6_convex_decomposition_4.stl" />
      </geometry>
    </collision>
    <collision>
      <origin rpy="0 0 0" xyz="0 0 0" />
      <geometry>
        <mesh filename="assets/embodiments/galbot-one-golf/urdf/meshes/collision/right_arm/right_arm_link6/convex_decomposition/right_arm_link6_convex_decomposition_5.stl" />
      </geometry>
    </collision>
    <collision>
      <origin rpy="0 0 0" xyz="0 0 0" />
      <geometry>
        <mesh filename="assets/embodiments/galbot-one-golf/urdf/meshes/collision/right_arm/right_arm_link6/convex_decomposition/right_arm_link6_convex_decomposition_6.stl" />
      </geometry>
    </collision>
    <collision>
      <origin rpy="0 0 0" xyz="0 0 0" />
      <geometry>
        <mesh filename="assets/embodiments/galbot-one-golf/urdf/meshes/collision/right_arm/right_arm_link6/convex_decomposition/right_arm_link6_convex_decomposition_7.stl" />
      </geometry>
    </collision>
    <collision>
      <origin rpy="0 0 0" xyz="0 0 0" />
      <geometry>
        <mesh filename="assets/embodiments/galbot-one-golf/urdf/meshes/collision/right_arm/right_arm_link6/convex_decomposition/right_arm_link6_convex_decomposition_8.stl" />
      </geometry>
    </collision>
    <collision>
      <origin rpy="0 0 0" xyz="0 0 0" />
      <geometry>
        <mesh filename="assets/embodiments/galbot-one-golf/urdf/meshes/collision/right_arm/right_arm_link6/convex_decomposition/right_arm_link6_convex_decomposition_9.stl" />
      </geometry>
    </collision>
    <collision>
      <origin rpy="0 0 0" xyz="0 0 0" />
      <geometry>
        <mesh filename="assets/embodiments/galbot-one-golf/urdf/meshes/collision/right_arm/right_arm_link6/convex_decomposition/right_arm_link6_convex_decomposition_10.stl" />
      </geometry>
    </collision>
    <collision>
      <origin rpy="0 0 0" xyz="0 0 0" />
      <geometry>
        <mesh filename="assets/embodiments/galbot-one-golf/urdf/meshes/collision/right_arm/right_arm_link6/convex_decomposition/right_arm_link6_convex_decomposition_11.stl" />
      </geometry>
    </collision>
    <collision>
      <origin rpy="0 0 0" xyz="0 0 0" />
      <geometry>
        <mesh filename="assets/embodiments/galbot-one-golf/urdf/meshes/collision/right_arm/right_arm_link6/convex_decomposition/right_arm_link6_convex_decomposition_12.stl" />
      </geometry>
    </collision>
    <collision>
      <origin rpy="0 0 0" xyz="0 0 0" />
      <geometry>
        <mesh filename="assets/embodiments/galbot-one-golf/urdf/meshes/collision/right_arm/right_arm_link6/convex_decomposition/right_arm_link6_convex_decomposition_13.stl" />
      </geometry>
    </collision>
    <collision>
      <origin rpy="0 0 0" xyz="0 0 0" />
      <geometry>
        <mesh filename="assets/embodiments/galbot-one-golf/urdf/meshes/collision/right_arm/right_arm_link6/convex_decomposition/right_arm_link6_convex_decomposition_14.stl" />
      </geometry>
    </collision>
    <collision>
      <origin rpy="0 0 0" xyz="0 0 0" />
      <geometry>
        <mesh filename="assets/embodiments/galbot-one-golf/urdf/meshes/collision/right_arm/right_arm_link6/convex_decomposition/right_arm_link6_convex_decomposition_15.stl" />
      </geometry>
    </collision>
    <collision>
      <origin rpy="0 0 0" xyz="0 0 0" />
      <geometry>
        <mesh filename="assets/embodiments/galbot-one-golf/urdf/meshes/collision/right_arm/right_arm_link6/convex_decomposition/right_arm_link6_convex_decomposition_16.stl" />
      </geometry>
    </collision>
    <collision>
      <origin rpy="0 0 0" xyz="0 0 0" />
      <geometry>
        <mesh filename="assets/embodiments/galbot-one-golf/urdf/meshes/collision/right_arm/right_arm_link6/convex_decomposition/right_arm_link6_convex_decomposition_17.stl" />
      </geometry>
    </collision>
  </link>
  <joint name="right_arm_joint6" type="revolute">
    <origin rpy="-1.2585432919892481 1.5571890594607201 -2.829366683877919" xyz="0.00062499703581863687 0.00090206115554246704 -3.7707127696758004e-06" />
    <parent link="right_arm_link5" />
    <child link="right_arm_link6" />
    <axis xyz="0 0 1" />
    <limit acceleration="2" effort="1000" jerk="12" lower="-0.7353981633974483" upper="0.8226646259971648" velocity="1000" />
  </joint>
  <link name="right_arm_link7">
    <inertial>
      <origin rpy="0 0 0" xyz="-0.05751 0.00684 0.011869999999999999" />
      <mass value="0.064" />
      <inertia ixx="9.40904e-05" ixy="2.70344e-05" ixz="1.3296e-05" iyy="0.000339148" iyz="6.872e-07" izz="0.0003341136" />
    </inertial>
    <visual>
      <origin rpy="0 0 0" xyz="0 0 0" />
      <geometry>
        <mesh filename="assets/embodiments/galbot-one-golf/urdf/meshes/visual/right_arm/right_arm_link7/obj/right_arm_link7.obj" />
      </geometry>
    </visual>
    <collision>
      <origin rpy="0 0 0" xyz="0 0 0" />
      <geometry>
        <mesh filename="assets/embodiments/galbot-one-golf/urdf/meshes/collision/right_arm/right_arm_link7/convex_decomposition/right_arm_link7_convex_decomposition_0.stl" />
      </geometry>
    </collision>
    <collision>
      <origin rpy="0 0 0" xyz="0 0 0" />
      <geometry>
        <mesh filename="assets/embodiments/galbot-one-golf/urdf/meshes/collision/right_arm/right_arm_link7/convex_decomposition/right_arm_link7_convex_decomposition_1.stl" />
      </geometry>
    </collision>
    <collision>
      <origin rpy="0 0 0" xyz="0 0 0" />
      <geometry>
        <mesh filename="assets/embodiments/galbot-one-golf/urdf/meshes/collision/right_arm/right_arm_link7/convex_decomposition/right_arm_link7_convex_decomposition_2.stl" />
      </geometry>
    </collision>
    <collision>
      <origin rpy="0 0 0" xyz="0 0 0" />
      <geometry>
        <mesh filename="assets/embodiments/galbot-one-golf/urdf/meshes/collision/right_arm/right_arm_link7/convex_decomposition/right_arm_link7_convex_decomposition_3.stl" />
      </geometry>
    </collision>
    <collision>
      <origin rpy="0 0 0" xyz="0 0 0" />
      <geometry>
        <mesh filename="assets/embodiments/galbot-one-golf/urdf/meshes/collision/right_arm/right_arm_link7/convex_decomposition/right_arm_link7_convex_decomposition_4.stl" />
      </geometry>
    </collision>
  </link>
  <joint name="right_arm_joint7" type="revolute">
    <origin rpy="-1.5707644402588077 0 0" xyz="0.00046808460296192677 0 0" />
    <parent link="right_arm_link6" />
    <child link="right_arm_link7" />
    <axis xyz="0 0 1" />
    <limit acceleration="2" effort="1000" jerk="12" lower="-1.538202778" upper="1.538202778" velocity="1000" />
  </joint>
  <link name="right_arm_end_effector_mount_link">
    <inertial>
      <origin rpy="0 0 0" xyz="0 0 0" />
      <mass value="0" />
      <inertia ixx="0" ixy="0" ixz="0" iyy="0" iyz="0" izz="0" />
    </inertial>
  </link>
  <joint name="right_arm_end_effector_mount_joint" type="fixed">
    <origin rpy="-3.1312413495362867 -0.010947553917230124 -3.1276344846654998" xyz="-0.10774748970811954 -0.0012972837648986128 0.00010593927032868949" />
    <parent link="right_arm_link7" />
    <child link="right_arm_end_effector_mount_link" />
    <axis xyz="0 0 0" />
  </joint>
  <joint name="left_arm_joint" type="fixed">
    <origin rpy="0 0 0" xyz="0 0 0" />
    <parent link="torso_left_arm_mount_link" />
    <child link="left_arm_base_link" />
  </joint>
  <link name="left_arm_base_link">
    <inertial>
      <origin rpy="0 0 0" xyz="0.0 0.0 -0.10506" />
      <mass value="0.92" />
      <inertia ixx="0.01075595" ixy="9e-08" ixz="4.1e-07" iyy="0.01077842" iyz="1.896e-05" izz="0.0007042000000000001" />
    </inertial>
  </link>
  <link name="left_arm_link1">
    <inertial>
      <origin rpy="0 0 0" xyz="0.0 0.0009699999999999999 -0.015390000000000001" />
      <mass value="0.128" />
      <inertia ixx="0.0002663848" ixy="1.5136e-06" ixz="5.52e-08" iyy="0.0002712968" iyz="2.3808e-06" izz="0.000132192" />
    </inertial>
    <visual>
      <origin rpy="0 0 0" xyz="0 0 0" />
      <geometry>
        <mesh filename="assets/embodiments/galbot-one-golf/urdf/meshes/visual/left_arm/left_arm_link1/obj/left_arm_link1.obj" />
      </geometry>
    </visual>
    <collision>
      <origin rpy="0 0 0" xyz="0 0 0" />
      <geometry>
        <mesh filename="assets/embodiments/galbot-one-golf/urdf/meshes/collision/left_arm/left_arm_link1/convex_decomposition/left_arm_link1_convex_decomposition_0.stl" />
      </geometry>
    </collision>
    <collision>
      <origin rpy="0 0 0" xyz="0 0 0" />
      <geometry>
        <mesh filename="assets/embodiments/galbot-one-golf/urdf/meshes/collision/left_arm/left_arm_link1/convex_decomposition/left_arm_link1_convex_decomposition_1.stl" />
      </geometry>
    </collision>
    <collision>
      <origin rpy="0 0 0" xyz="0 0 0" />
      <geometry>
        <mesh filename="assets/embodiments/galbot-one-golf/urdf/meshes/collision/left_arm/left_arm_link1/convex_decomposition/left_arm_link1_convex_decomposition_2.stl" />
      </geometry>
    </collision>
    <collision>
      <origin rpy="0 0 0" xyz="0 0 0" />
      <geometry>
        <mesh filename="assets/embodiments/galbot-one-golf/urdf/meshes/collision/left_arm/left_arm_link1/convex_decomposition/left_arm_link1_convex_decomposition_3.stl" />
      </geometry>
    </collision>
    <collision>
      <origin rpy="0 0 0" xyz="0 0 0" />
      <geometry>
        <mesh filename="assets/embodiments/galbot-one-golf/urdf/meshes/collision/left_arm/left_arm_link1/convex_decomposition/left_arm_link1_convex_decomposition_4.stl" />
      </geometry>
    </collision>
    <collision>
      <origin rpy="0 0 0" xyz="0 0 0" />
      <geometry>
        <mesh filename="assets/embodiments/galbot-one-golf/urdf/meshes/collision/left_arm/left_arm_link1/convex_decomposition/left_arm_link1_convex_decomposition_5.stl" />
      </geometry>
    </collision>
    <collision>
      <origin rpy="0 0 0" xyz="0 0 0" />
      <geometry>
        <mesh filename="assets/embodiments/galbot-one-golf/urdf/meshes/collision/left_arm/left_arm_link1/convex_decomposition/left_arm_link1_convex_decomposition_6.stl" />
      </geometry>
    </collision>
    <collision>
      <origin rpy="0 0 0" xyz="0 0 0" />
      <geometry>
        <mesh filename="assets/embodiments/galbot-one-golf/urdf/meshes/collision/left_arm/left_arm_link1/convex_decomposition/left_arm_link1_convex_decomposition_7.stl" />
      </geometry>
    </collision>
    <collision>
      <origin rpy="0 0 0" xyz="0 0 0" />
      <geometry>
        <mesh filename="assets/embodiments/galbot-one-golf/urdf/meshes/collision/left_arm/left_arm_link1/convex_decomposition/left_arm_link1_convex_decomposition_8.stl" />
      </geometry>
    </collision>
    <collision>
      <origin rpy="0 0 0" xyz="0 0 0" />
      <geometry>
        <mesh filename="assets/embodiments/galbot-one-golf/urdf/meshes/collision/left_arm/left_arm_link1/convex_decomposition/left_arm_link1_convex_decomposition_9.stl" />
      </geometry>
    </collision>
    <collision>
      <origin rpy="0 0 0" xyz="0 0 0" />
      <geometry>
        <mesh filename="assets/embodiments/galbot-one-golf/urdf/meshes/collision/left_arm/left_arm_link1/convex_decomposition/left_arm_link1_convex_decomposition_10.stl" />
      </geometry>
    </collision>
    <collision>
      <origin rpy="0 0 0" xyz="0 0 0" />
      <geometry>
        <mesh filename="assets/embodiments/galbot-one-golf/urdf/meshes/collision/left_arm/left_arm_link1/convex_decomposition/left_arm_link1_convex_decomposition_11.stl" />
      </geometry>
    </collision>
  </link>
  <joint name="left_arm_joint1" type="revolute">
    <origin rpy="0 0 0.523598775598286" xyz="0 0 0" />
    <parent link="left_arm_base_link" />
    <child link="left_arm_link1" />
    <axis xyz="0 0 1" />
    <limit acceleration="2" effort="1000" jerk="12" lower="-3.00432619" upper="3.00432619" velocity="1000" />
  </joint>
  <link name="left_arm_link2">
    <inertial>
      <origin rpy="0 0 0" xyz="0.0 0.09558 0.010150000000000001" />
      <mass value="0.1144" />
      <inertia ixx="0.0015503048" ixy="1.6e-08" ixz="9.6e-09" iyy="0.0001263312" iyz="1.56624e-05" izz="0.0015161448" />
    </inertial>
    <visual>
      <origin rpy="0 0 0" xyz="0 0 0" />
      <geometry>
        <mesh filename="assets/embodiments/galbot-one-golf/urdf/meshes/visual/left_arm/left_arm_link2/obj/left_arm_link2.obj" />
      </geometry>
    </visual>
    <collision>
      <origin rpy="0 0 0" xyz="0 0 0" />
      <geometry>
        <mesh filename="assets/embodiments/galbot-one-golf/urdf/meshes/collision/left_arm/left_arm_link2/convex_decomposition/left_arm_link2_convex_decomposition_0.stl" />
      </geometry>
    </collision>
    <collision>
      <origin rpy="0 0 0" xyz="0 0 0" />
      <geometry>
        <mesh filename="assets/embodiments/galbot-one-golf/urdf/meshes/collision/left_arm/left_arm_link2/convex_decomposition/left_arm_link2_convex_decomposition_1.stl" />
      </geometry>
    </collision>
    <collision>
      <origin rpy="0 0 0" xyz="0 0 0" />
      <geometry>
        <mesh filename="assets/embodiments/galbot-one-golf/urdf/meshes/collision/left_arm/left_arm_link2/convex_decomposition/left_arm_link2_convex_decomposition_2.stl" />
      </geometry>
    </collision>
    <collision>
      <origin rpy="0 0 0" xyz="0 0 0" />
      <geometry>
        <mesh filename="assets/embodiments/galbot-one-golf/urdf/meshes/collision/left_arm/left_arm_link2/convex_decomposition/left_arm_link2_convex_decomposition_3.stl" />
      </geometry>
    </collision>
    <collision>
      <origin rpy="0 0 0" xyz="0 0 0" />
      <geometry>
        <mesh filename="assets/embodiments/galbot-one-golf/urdf/meshes/collision/left_arm/left_arm_link2/convex_decomposition/left_arm_link2_convex_decomposition_4.stl" />
      </geometry>
    </collision>
    <collision>
      <origin rpy="0 0 0" xyz="0 0 0" />
      <geometry>
        <mesh filename="assets/embodiments/galbot-one-golf/urdf/meshes/collision/left_arm/left_arm_link2/convex_decomposition/left_arm_link2_convex_decomposition_5.stl" />
      </geometry>
    </collision>
    <collision>
      <origin rpy="0 0 0" xyz="0 0 0" />
      <geometry>
        <mesh filename="assets/embodiments/galbot-one-golf/urdf/meshes/collision/left_arm/left_arm_link2/convex_decomposition/left_arm_link2_convex_decomposition_6.stl" />
      </geometry>
    </collision>
  </link>
  <joint name="left_arm_joint2" type="revolute">
    <origin rpy="1.575674381050491 -0.027299082814065567 3.1414595026668941" xyz="-0.00013437017583159253 -0.00018894773990115699 9.2136120511708617e-07" />
    <parent link="left_arm_link1" />
    <child link="left_arm_link2" />
    <axis xyz="0 0 1" />
    <limit acceleration="2" effort="1000" jerk="12" lower="-1.608062789" upper="1.608062789" velocity="1000" />
  </joint>
  <link name="left_arm_link3">
    <inertial>
      <origin rpy="0 0 0" xyz="0.0 0.00088 -0.04936" />
      <mass value="0.1144" />
      <inertia ixx="0.0009499656" ixy="1.2e-08" ixz="6.8e-08" iyy="0.0009430072000000001" iyz="8.038400000000001e-06" izz="0.00010972" />
    </inertial>
    <visual>
      <origin rpy="0 0 0" xyz="0 0 0" />
      <geometry>
        <mesh filename="assets/embodiments/galbot-one-golf/urdf/meshes/visual/left_arm/left_arm_link3/obj/left_arm_link3.obj" />
      </geometry>
    </visual>
    <collision>
      <origin rpy="0 0 0" xyz="0 0 0" />
      <geometry>
        <mesh filename="assets/embodiments/galbot-one-golf/urdf/meshes/collision/left_arm/left_arm_link3/convex_decomposition/left_arm_link3_convex_decomposition_0.stl" />
      </geometry>
    </collision>
    <collision>
      <origin rpy="0 0 0" xyz="0 0 0" />
      <geometry>
        <mesh filename="assets/embodiments/galbot-one-golf/urdf/meshes/collision/left_arm/left_arm_link3/convex_decomposition/left_arm_link3_convex_decomposition_1.stl" />
      </geometry>
    </collision>
    <collision>
      <origin rpy="0 0 0" xyz="0 0 0" />
      <geometry>
        <mesh filename="assets/embodiments/galbot-one-golf/urdf/meshes/collision/left_arm/left_arm_link3/convex_decomposition/left_arm_link3_convex_decomposition_2.stl" />
      </geometry>
    </collision>
  </link>
  <joint name="left_arm_joint3" type="revolute">
    <origin rpy="1.5685129114291423 1.0430330028013697 3.1396199288375595" xyz="0.00023714746172431324 0.35025715938483493 0.0004027722296788272" />
    <parent link="left_arm_link2" />
    <child link="left_arm_link3" />
    <axis xyz="0 0 1" />
    <limit acceleration="2" effort="1000" jerk="12" lower="-2.916972222" upper="2.916972222" velocity="1000" />
  </joint>
  <link name="left_arm_link4">
    <inertial>
      <origin rpy="0 0 0" xyz="0.0 0.05614 0.019170000000000003" />
      <mass value="0.08800000000000001" />
      <inertia ixx="0.0005611104" ixy="2.56e-08" ixz="9.28e-08" iyy="0.0001294832" iyz="2.71552e-05" izz="0.0005200959999999999" />
    </inertial>
    <visual>
      <origin rpy="0 0 0" xyz="0 0 0" />
      <geometry>
        <mesh filename="assets/embodiments/galbot-one-golf/urdf/meshes/visual/left_arm/left_arm_link4/obj/left_arm_link4.obj" />
      </geometry>
    </visual>
    <collision>
      <origin rpy="0 0 0" xyz="0 0 0" />
      <geometry>
        <mesh filename="assets/embodiments/galbot-one-golf/urdf/meshes/collision/left_arm/left_arm_link4/convex_decomposition/left_arm_link4_convex_decomposition_0.stl" />
      </geometry>
    </collision>
    <collision>
      <origin rpy="0 0 0" xyz="0 0 0" />
      <geometry>
        <mesh filename="assets/embodiments/galbot-one-golf/urdf/meshes/collision/left_arm/left_arm_link4/convex_decomposition/left_arm_link4_convex_decomposition_1.stl" />
      </geometry>
    </collision>
    <collision>
      <origin rpy="0 0 0" xyz="0 0 0" />
      <geometry>
        <mesh filename="assets/embodiments/galbot-one-golf/urdf/meshes/collision/left_arm/left_arm_link4/convex_decomposition/left_arm_link4_convex_decomposition_2.stl" />
      </geometry>
    </collision>
    <collision>
      <origin rpy="0 0 0" xyz="0 0 0" />
      <geometry>
        <mesh filename="assets/embodiments/galbot-one-golf/urdf/meshes/collision/left_arm/left_arm_link4/convex_decomposition/left_arm_link4_convex_decomposition_3.stl" />
      </geometry>
    </collision>
    <collision>
      <origin rpy="0 0 0" xyz="0 0 0" />
      <geometry>
        <mesh filename="assets/embodiments/galbot-one-golf/urdf/meshes/collision/left_arm/left_arm_link4/convex_decomposition/left_arm_link4_convex_decomposition_4.stl" />
      </geometry>
    </collision>
    <collision>
      <origin rpy="0 0 0" xyz="0 0 0" />
      <geometry>
        <mesh filename="assets/embodiments/galbot-one-golf/urdf/meshes/collision/left_arm/left_arm_link4/convex_decomposition/left_arm_link4_convex_decomposition_5.stl" />
      </geometry>
    </collision>
    <collision>
      <origin rpy="0 0 0" xyz="0 0 0" />
      <geometry>
        <mesh filename="assets/embodiments/galbot-one-golf/urdf/meshes/collision/left_arm/left_arm_link4/convex_decomposition/left_arm_link4_convex_decomposition_6.stl" />
      </geometry>
    </collision>
  </link>
  <joint name="left_arm_joint4" type="revolute">
    <origin rpy="1.572419387879767 4.7815258235717195e-05 -3.14159257598264" xyz="-3.7543997451416462e-05 0.00055336723805938951 -8.9814961738298067e-07" />
    <parent link="left_arm_link3" />
    <child link="left_arm_link4" />
    <axis xyz="0 0 1" />
    <limit acceleration="2" effort="1000" jerk="12" lower="-2.5679938779914944" upper="1.869862177" velocity="1000" />
  </joint>
  <link name="left_arm_link5">
    <inertial>
      <origin rpy="0 0 0" xyz="0.00044 0.0016899999999999999 -0.13306" />
      <mass value="0.092" />
      <inertia ixx="0.0020647944" ixy="1.584e-06" ixz="4.484e-06" iyy="0.0020242504" iyz="1.67456e-05" izz="9.26784e-05" />
    </inertial>
    <visual>
      <origin rpy="0 0 0" xyz="0 0 0" />
      <geometry>
        <mesh filename="assets/embodiments/galbot-one-golf/urdf/meshes/visual/left_arm/left_arm_link5/obj/left_arm_link5.obj" />
      </geometry>
    </visual>
    <collision>
      <origin rpy="0 0 0" xyz="0 0 0" />
      <geometry>
        <mesh filename="assets/embodiments/galbot-one-golf/urdf/meshes/collision/left_arm/left_arm_link5/convex_decomposition/left_arm_link5_convex_decomposition_0.stl" />
      </geometry>
    </collision>
    <collision>
      <origin rpy="0 0 0" xyz="0 0 0" />
      <geometry>
        <mesh filename="assets/embodiments/galbot-one-golf/urdf/meshes/collision/left_arm/left_arm_link5/convex_decomposition/left_arm_link5_convex_decomposition_1.stl" />
      </geometry>
    </collision>
    <collision>
      <origin rpy="0 0 0" xyz="0 0 0" />
      <geometry>
        <mesh filename="assets/embodiments/galbot-one-golf/urdf/meshes/collision/left_arm/left_arm_link5/convex_decomposition/left_arm_link5_convex_decomposition_2.stl" />
      </geometry>
    </collision>
  </link>
  <joint name="left_arm_joint5" type="revolute">
    <origin rpy="-1.5752182314133325 0.0075632949495085811 -3.3444067983001702e-05" xyz="-0.00032340473458849291 0.36022238810105106 -0.0015928338638491746" />
    <parent link="left_arm_link4" />
    <child link="left_arm_link5" />
    <axis xyz="0 0 1" />
    <limit acceleration="2" effort="1000" jerk="12" lower="-2.916972222" upper="2.916972222" velocity="1000" />
  </joint>
  <link name="left_arm_link6">
    <inertial>
      <origin rpy="0 0 0" xyz="-0.00088 -0.0072699999999999996 -0.00011999999999999999" />
      <mass value="0.0376" />
      <inertia ixx="2.20456e-05" ixy="6.320000000000001e-08" ixz="1.184e-07" iyy="2.31824e-05" iyz="1.8e-07" izz="2.37472e-05" />
    </inertial>
    <visual>
      <origin rpy="0 0 0" xyz="0 0 0" />
      <geometry>
        <mesh filename="assets/embodiments/galbot-one-golf/urdf/meshes/visual/left_arm/left_arm_link6/obj/left_arm_link6.obj" />
      </geometry>
    </visual>
    <collision>
      <origin rpy="0 0 0" xyz="0 0 0" />
      <geometry>
        <mesh filename="assets/embodiments/galbot-one-golf/urdf/meshes/collision/left_arm/left_arm_link6/convex_decomposition/left_arm_link6_convex_decomposition_0.stl" />
      </geometry>
    </collision>
    <collision>
      <origin rpy="0 0 0" xyz="0 0 0" />
      <geometry>
        <mesh filename="assets/embodiments/galbot-one-golf/urdf/meshes/collision/left_arm/left_arm_link6/convex_decomposition/left_arm_link6_convex_decomposition_1.stl" />
      </geometry>
    </collision>
    <collision>
      <origin rpy="0 0 0" xyz="0 0 0" />
      <geometry>
        <mesh filename="assets/embodiments/galbot-one-golf/urdf/meshes/collision/left_arm/left_arm_link6/convex_decomposition/left_arm_link6_convex_decomposition_2.stl" />
      </geometry>
    </collision>
    <collision>
      <origin rpy="0 0 0" xyz="0 0 0" />
      <geometry>
        <mesh filename="assets/embodiments/galbot-one-golf/urdf/meshes/collision/left_arm/left_arm_link6/convex_decomposition/left_arm_link6_convex_decomposition_3.stl" />
      </geometry>
    </collision>
    <collision>
      <origin rpy="0 0 0" xyz="0 0 0" />
      <geometry>
        <mesh filename="assets/embodiments/galbot-one-golf/urdf/meshes/collision/left_arm/left_arm_link6/convex_decomposition/left_arm_link6_convex_decomposition_4.stl" />
      </geometry>
    </collision>
    <collision>
      <origin rpy="0 0 0" xyz="0 0 0" />
      <geometry>
        <mesh filename="assets/embodiments/galbot-one-golf/urdf/meshes/collision/left_arm/left_arm_link6/convex_decomposition/left_arm_link6_convex_decomposition_5.stl" />
      </geometry>
    </collision>
    <collision>
      <origin rpy="0 0 0" xyz="0 0 0" />
      <geometry>
        <mesh filename="assets/embodiments/galbot-one-golf/urdf/meshes/collision/left_arm/left_arm_link6/convex_decomposition/left_arm_link6_convex_decomposition_6.stl" />
      </geometry>
    </collision>
    <collision>
      <origin rpy="0 0 0" xyz="0 0 0" />
      <geometry>
        <mesh filename="assets/embodiments/galbot-one-golf/urdf/meshes/collision/left_arm/left_arm_link6/convex_decomposition/left_arm_link6_convex_decomposition_7.stl" />
      </geometry>
    </collision>
    <collision>
      <origin rpy="0 0 0" xyz="0 0 0" />
      <geometry>
        <mesh filename="assets/embodiments/galbot-one-golf/urdf/meshes/collision/left_arm/left_arm_link6/convex_decomposition/left_arm_link6_convex_decomposition_8.stl" />
      </geometry>
    </collision>
    <collision>
      <origin rpy="0 0 0" xyz="0 0 0" />
      <geometry>
        <mesh filename="assets/embodiments/galbot-one-golf/urdf/meshes/collision/left_arm/left_arm_link6/convex_decomposition/left_arm_link6_convex_decomposition_9.stl" />
      </geometry>
    </collision>
    <collision>
      <origin rpy="0 0 0" xyz="0 0 0" />
      <geometry>
        <mesh filename="assets/embodiments/galbot-one-golf/urdf/meshes/collision/left_arm/left_arm_link6/convex_decomposition/left_arm_link6_convex_decomposition_10.stl" />
      </geometry>
    </collision>
    <collision>
      <origin rpy="0 0 0" xyz="0 0 0" />
      <geometry>
        <mesh filename="assets/embodiments/galbot-one-golf/urdf/meshes/collision/left_arm/left_arm_link6/convex_decomposition/left_arm_link6_convex_decomposition_11.stl" />
      </geometry>
    </collision>
    <collision>
      <origin rpy="0 0 0" xyz="0 0 0" />
      <geometry>
        <mesh filename="assets/embodiments/galbot-one-golf/urdf/meshes/collision/left_arm/left_arm_link6/convex_decomposition/left_arm_link6_convex_decomposition_12.stl" />
      </geometry>
    </collision>
    <collision>
      <origin rpy="0 0 0" xyz="0 0 0" />
      <geometry>
        <mesh filename="assets/embodiments/galbot-one-golf/urdf/meshes/collision/left_arm/left_arm_link6/convex_decomposition/left_arm_link6_convex_decomposition_13.stl" />
      </geometry>
    </collision>
    <collision>
      <origin rpy="0 0 0" xyz="0 0 0" />
      <geometry>
        <mesh filename="assets/embodiments/galbot-one-golf/urdf/meshes/collision/left_arm/left_arm_link6/convex_decomposition/left_arm_link6_convex_decomposition_14.stl" />
      </geometry>
    </collision>
    <collision>
      <origin rpy="0 0 0" xyz="0 0 0" />
      <geometry>
        <mesh filename="assets/embodiments/galbot-one-golf/urdf/meshes/collision/left_arm/left_arm_link6/convex_decomposition/left_arm_link6_convex_decomposition_15.stl" />
      </geometry>
    </collision>
    <collision>
      <origin rpy="0 0 0" xyz="0 0 0" />
      <geometry>
        <mesh filename="assets/embodiments/galbot-one-golf/urdf/meshes/collision/left_arm/left_arm_link6/convex_decomposition/left_arm_link6_convex_decomposition_16.stl" />
      </geometry>
    </collision>
    <collision>
      <origin rpy="0 0 0" xyz="0 0 0" />
      <geometry>
        <mesh filename="assets/embodiments/galbot-one-golf/urdf/meshes/collision/left_arm/left_arm_link6/convex_decomposition/left_arm_link6_convex_decomposition_17.stl" />
      </geometry>
    </collision>
    <collision>
      <origin rpy="0 0 0" xyz="0 0 0" />
      <geometry>
        <mesh filename="assets/embodiments/galbot-one-golf/urdf/meshes/collision/left_arm/left_arm_link6/convex_decomposition/left_arm_link6_convex_decomposition_18.stl" />
      </geometry>
    </collision>
    <collision>
      <origin rpy="0 0 0" xyz="0 0 0" />
      <geometry>
        <mesh filename="assets/embodiments/galbot-one-golf/urdf/meshes/collision/left_arm/left_arm_link6/convex_decomposition/left_arm_link6_convex_decomposition_19.stl" />
      </geometry>
    </collision>
  </link>
  <joint name="left_arm_joint6" type="revolute">
    <origin rpy="2.0315174356233152 1.5668156817098189 0.46071795368637569" xyz="0.00042730502856495899 -0.00044875973651078022 -7.9420133369329437e-07" />
    <parent link="left_arm_link5" />
    <child link="left_arm_link6" />
    <axis xyz="0 0 1" />
    <limit acceleration="2" effort="1000" jerk="12" lower="-0.8226646259971648" upper="0.7353981633974483" velocity="1000" />
  </joint>
  <link name="left_arm_link7">
    <inertial>
      <origin rpy="0 0 0" xyz="-0.05776 -0.00675 0.011349999999999999" />
      <mass value="0.064" />
      <inertia ixx="9.310000000000001e-05" ixy="2.65888e-05" ixz="1.18952e-05" iyy="0.0003392096" iyz="5.256000000000001e-07" izz="0.0003351032" />
    </inertial>
    <visual>
      <origin rpy="0 0 0" xyz="0 0 0" />
      <geometry>
        <mesh filename="assets/embodiments/galbot-one-golf/urdf/meshes/visual/left_arm/left_arm_link7/obj/left_arm_link7.obj" />
      </geometry>
    </visual>
    <collision>
      <origin rpy="0 0 0" xyz="0 0 0" />
      <geometry>
        <mesh filename="assets/embodiments/galbot-one-golf/urdf/meshes/collision/left_arm/left_arm_link7/convex_decomposition/left_arm_link7_convex_decomposition_0.stl" />
      </geometry>
    </collision>
    <collision>
      <origin rpy="0 0 0" xyz="0 0 0" />
      <geometry>
        <mesh filename="assets/embodiments/galbot-one-golf/urdf/meshes/collision/left_arm/left_arm_link7/convex_decomposition/left_arm_link7_convex_decomposition_1.stl" />
      </geometry>
    </collision>
    <collision>
      <origin rpy="0 0 0" xyz="0 0 0" />
      <geometry>
        <mesh filename="assets/embodiments/galbot-one-golf/urdf/meshes/collision/left_arm/left_arm_link7/convex_decomposition/left_arm_link7_convex_decomposition_2.stl" />
      </geometry>
    </collision>
    <collision>
      <origin rpy="0 0 0" xyz="0 0 0" />
      <geometry>
        <mesh filename="assets/embodiments/galbot-one-golf/urdf/meshes/collision/left_arm/left_arm_link7/convex_decomposition/left_arm_link7_convex_decomposition_3.stl" />
      </geometry>
    </collision>
    <collision>
      <origin rpy="0 0 0" xyz="0 0 0" />
      <geometry>
        <mesh filename="assets/embodiments/galbot-one-golf/urdf/meshes/collision/left_arm/left_arm_link7/convex_decomposition/left_arm_link7_convex_decomposition_4.stl" />
      </geometry>
    </collision>
  </link>
  <joint name="left_arm_joint7" type="revolute">
    <origin rpy="1.5724117266239364 0 0" xyz="0.00019700373826198809 0 0" />
    <parent link="left_arm_link6" />
    <child link="left_arm_link7" />
    <axis xyz="0 0 1" />
    <limit acceleration="2" effort="1000" jerk="12" lower="-1.538202778" upper="1.538202778" velocity="1000" />
  </joint>
  <link name="left_arm_end_effector_mount_link">
    <inertial>
      <origin rpy="0 0 0" xyz="0 0 0" />
      <mass value="0" />
      <inertia ixx="0" ixy="0" ixz="0" iyy="0" iyz="0" izz="0" />
    </inertial>
  </link>
  <joint name="left_arm_end_effector_mount_joint" type="fixed">
    <origin rpy="-3.1229997976800092 0.00074659929782749934 3.1131960251529955" xyz="-0.10882974527891312 0.00041524921680126224 0.00016438102185557102" />
    <parent link="left_arm_link7" />
    <child link="left_arm_end_effector_mount_link" />
    <axis xyz="0 0 0" />
  </joint>
  <joint name="right_gripper_joint" type="fixed">
    <origin rpy="1.5707963267948966 0 0" xyz="0 0 0" />
    <parent link="right_arm_end_effector_mount_link" />
    <child link="right_gripper_flange_link" />
  </joint>
  <link name="right_gripper_flange_link">
    <inertial>
      <origin rpy="0 0 0" xyz="0.0030662 -1.4019E-18 3.383E-18" />
      <mass value="0.031005" />
      <inertia ixx="2.2585E-05" ixy="-2.0366E-21" ixz="-3.7461E-22" iyy="1.141E-05" iyz="-7.8518E-23" izz="1.141E-05" />
    </inertial>
    <visual>
      <geometry>
        <mesh filename="assets/embodiments/galbot-one-golf/urdf/meshes/visual/gripper/galbot_gripper1/flange_link.obj" />
      </geometry>
    </visual>
  </link>
  <joint name="right_gripper_base_joint" type="fixed">
    <origin rpy="0 0 0" xyz="0.0065 0 0" />
    <parent link="right_gripper_flange_link" />
    <child link="right_gripper_base_link" />
    <axis xyz="0 0 0" />
  </joint>
  <link name="right_gripper_base_link">
    <inertial>
      <origin rpy="0 0 0" xyz="0.037051 -6.4001E-05 6.4706E-05" />
      <mass value="0.061747" />
      <inertia ixx="2.5813E-05" ixy="4.7224E-08" ixz="-3.9403E-11" iyy="7.2859E-05" iyz="-2.962E-10" izz="5.7173E-05" />
    </inertial>
    <visual>
      <geometry>
        <mesh filename="assets/embodiments/galbot-one-golf/urdf/meshes/visual/gripper/galbot_gripper1/base_link.obj" />
      </geometry>
    </visual>
  </link>
  <link name="right_gripper_l_knuckle_link">
    <inertial>
      <origin rpy="0 0 0" xyz="0.024101 0 0" />
      <mass value="0.0070682" />
      <inertia ixx="9.2131e-08" ixy="0" ixz="0" iyy="1.559e-06" iyz="0" izz="1.4931e-06" />
    </inertial>
    <visual>
      <geometry>
        <mesh filename="assets/embodiments/galbot-one-golf/urdf/meshes/visual/gripper/galbot_gripper1/l_link_1.obj" />
      </geometry>
    </visual>
  </link>
  <link name="right_gripper_l_inner_knuckle_link">
    <inertial>
      <origin rpy="0 0 0" xyz="0.023769 0 0" />
      <mass value="0.007802" />
      <inertia ixx="1.044e-07" ixy="0" ixz="0" iyy="1.6385e-06" iyz="0" izz="1.566e-06" />
    </inertial>
    <visual>
      <geometry>
        <mesh filename="assets/embodiments/galbot-one-golf/urdf/meshes/visual/gripper/galbot_gripper1/l_link_2.obj" />
      </geometry>
    </visual>
  </link>
  <joint name="right_gripper_l_inner_knuckle_joint" type="revolute">
    <parent link="right_gripper_base_link" />
    <child link="right_gripper_l_inner_knuckle_link" />
    <origin rpy="1.5707963267948966 1.2465 0" xyz="0.079 0 -0.026" />
    <axis xyz="0 0 1" />
    <limit effort="1000" lower="-3.13" upper="3.13" velocity="2.0" />
  </joint>
  <link name="right_gripper_l_finger_link">
    <inertial>
      <origin rpy="0 0 0" xyz="0.016809 0.0019094 0" />
      <mass value="0.1" />
      <inertia ixx="3.4734e-06" ixy="0" ixz="0" iyy="1.1619e-05" iyz="0" izz="9.563e-06" />
    </inertial>
    <visual>
      <geometry>
        <mesh filename="assets/embodiments/galbot-one-golf/urdf/meshes/visual/gripper/galbot_gripper1/l_link_3_zhitao.obj" />
      </geometry>
    </visual>
    <collision>
      <origin rpy="0 0 0" xyz="0 0 0" />
      <geometry>
        <mesh filename="assets/embodiments/galbot-one-golf/urdf/meshes/collision/gripper/galbot_gripper1/convex_decomposition/l_link_3_zhitao_convex_decomposition/l_link_3_zhitao_convex_decomposition_0.stl" />
      </geometry>
    </collision>
    <collision>
      <origin rpy="0 0 0" xyz="0 0 0" />
      <geometry>
        <mesh filename="assets/embodiments/galbot-one-golf/urdf/meshes/collision/gripper/galbot_gripper1/convex_decomposition/l_link_3_zhitao_convex_decomposition/l_link_3_zhitao_convex_decomposition_1.stl" />
      </geometry>
    </collision>
    <collision>
      <origin rpy="0 0 0" xyz="0 0 0" />
      <geometry>
        <mesh filename="assets/embodiments/galbot-one-golf/urdf/meshes/collision/gripper/galbot_gripper1/convex_decomposition/l_link_3_zhitao_convex_decomposition/l_link_3_zhitao_convex_decomposition_2.stl" />
      </geometry>
    </collision>
    <collision>
      <origin rpy="0 0 0" xyz="0 0 0" />
      <geometry>
        <mesh filename="assets/embodiments/galbot-one-golf/urdf/meshes/collision/gripper/galbot_gripper1/convex_decomposition/l_link_3_zhitao_convex_decomposition/l_link_3_zhitao_convex_decomposition_3.stl" />
      </geometry>
    </collision>
    <collision>
      <origin rpy="0 0 0" xyz="0 0 0" />
      <geometry>
        <mesh filename="assets/embodiments/galbot-one-golf/urdf/meshes/collision/gripper/galbot_gripper1/convex_decomposition/l_link_3_zhitao_convex_decomposition/l_link_3_zhitao_convex_decomposition_4.stl" />
      </geometry>
    </collision>
    <collision>
      <origin rpy="0 0 0" xyz="0 0 0" />
      <geometry>
        <mesh filename="assets/embodiments/galbot-one-golf/urdf/meshes/collision/gripper/galbot_gripper1/convex_decomposition/l_link_3_zhitao_convex_decomposition/l_link_3_zhitao_convex_decomposition_5.stl" />
      </geometry>
    </collision>
  </link>
  <joint name="right_gripper_l_finger_joint" type="revolute">
    <parent link="right_gripper_l_inner_knuckle_link" />
    <child link="right_gripper_l_finger_link" />
    <origin rpy="0 0 1.2465" xyz="0.045 0 0" />
    <axis xyz="0 0 1" />
    <limit effort="1000" lower="-3.13" upper="3.13" velocity="2.0" />
  </joint>
  <link name="right_gripper_r_knuckle_link">
    <inertial>
      <origin rpy="0 0 0" xyz="0.024101 0 0" />
      <mass value="0.0070682" />
      <inertia ixx="9.2131e-08" ixy="0" ixz="0" iyy="1.559e-06" iyz="0" izz="1.4931e-06" />
    </inertial>
    <visual>
      <geometry>
        <mesh filename="assets/embodiments/galbot-one-golf/urdf/meshes/visual/gripper/galbot_gripper1/r_link_1.obj" />
      </geometry>
    </visual>
  </link>
  <link name="right_gripper_r_inner_knuckle_link">
    <inertial>
      <origin rpy="0 0 0" xyz="0.023769 0 0" />
      <mass value="0.007802" />
      <inertia ixx="1.044e-07" ixy="0" ixz="0" iyy="1.6385e-06" iyz="0" izz="1.566e-06" />
    </inertial>
    <visual>
      <geometry>
        <mesh filename="assets/embodiments/galbot-one-golf/urdf/meshes/visual/gripper/galbot_gripper1/r_link_2.obj" />
      </geometry>
    </visual>
  </link>
  <joint name="right_gripper_r_inner_knuckle_joint" type="revolute">
    <parent link="right_gripper_base_link" />
    <child link="right_gripper_r_inner_knuckle_link" />
    <origin rpy="1.5707963267948966 -1.2465 0" xyz="0.079 0 0.026" />
    <axis xyz="0 0 1" />
    <limit effort="1000" lower="-3.13" upper="3.13" velocity="2.0" />
  </joint>
  <link name="right_gripper_r_finger_link">
    <inertial>
      <origin rpy="0 0 0" xyz="0.016809 -0.0019094 0" />
      <mass value="0.1" />
      <inertia ixx="3.4734e-06" ixy="0" ixz="0" iyy="1.1619e-05" iyz="0" izz="9.563e-06" />
    </inertial>
    <visual>
      <geometry>
        <mesh filename="assets/embodiments/galbot-one-golf/urdf/meshes/visual/gripper/galbot_gripper1/r_link_3_zhitao.obj" />
      </geometry>
    </visual>
    <collision>
      <origin rpy="0 0 0" xyz="0 0 0" />
      <geometry>
        <mesh filename="assets/embodiments/galbot-one-golf/urdf/meshes/collision/gripper/galbot_gripper1/convex_decomposition/r_link_3_zhitao_convex_decomposition/r_link_3_zhitao_convex_decomposition_0.stl" />
      </geometry>
    </collision>
    <collision>
      <origin rpy="0 0 0" xyz="0 0 0" />
      <geometry>
        <mesh filename="assets/embodiments/galbot-one-golf/urdf/meshes/collision/gripper/galbot_gripper1/convex_decomposition/r_link_3_zhitao_convex_decomposition/r_link_3_zhitao_convex_decomposition_1.stl" />
      </geometry>
    </collision>
    <collision>
      <origin rpy="0 0 0" xyz="0 0 0" />
      <geometry>
        <mesh filename="assets/embodiments/galbot-one-golf/urdf/meshes/collision/gripper/galbot_gripper1/convex_decomposition/r_link_3_zhitao_convex_decomposition/r_link_3_zhitao_convex_decomposition_2.stl" />
      </geometry>
    </collision>
    <collision>
      <origin rpy="0 0 0" xyz="0 0 0" />
      <geometry>
        <mesh filename="assets/embodiments/galbot-one-golf/urdf/meshes/collision/gripper/galbot_gripper1/convex_decomposition/r_link_3_zhitao_convex_decomposition/r_link_3_zhitao_convex_decomposition_3.stl" />
      </geometry>
    </collision>
  </link>
  <joint name="right_gripper_r_finger_joint" type="revolute">
    <parent link="right_gripper_r_inner_knuckle_link" />
    <child link="right_gripper_r_finger_link" />
    <origin rpy="0 0 -1.2465" xyz="0.045 0 0" />
    <axis xyz="0 0 1" />
    <limit effort="1000" lower="-3.13" upper="3.13" velocity="2.0" />
  </joint>
  <joint name="right_gripper_r_knuckle_joint" type="revolute">
    <parent link="right_gripper_base_link" />
    <child link="right_gripper_r_knuckle_link" />
    <origin rpy="1.5707963267948966 -1.2465 0" xyz="0.0745 0 0.0385" />
    <axis xyz="0 0 -1" />
    <limit effort="1000" lower="0.0" upper="1.703" velocity="20.0" />
  </joint>
  <joint name="right_gripper_l_knuckle_joint" type="revolute">
    <parent link="right_gripper_base_link" />
    <child link="right_gripper_l_knuckle_link" />
    <origin rpy="1.5707963267948966 1.2465 0" xyz="0.0745 0 -0.0385" />
    <axis xyz="0 0 1" />
    <limit effort="1000" lower="-3.13" upper="3.13" velocity="20.0" />
  </joint>
  <link name="right_gripper_tcp_link" />
  <joint name="right_gripper_tcp_joint" type="fixed">
    <parent link="right_gripper_base_link" />
    <child link="right_gripper_tcp_link" />
    <origin rpy="-1.5707963267948966 0 0" xyz="0.1470480202320212 0 0" />
  </joint>
  <joint name="right_joint" type="fixed">
    <origin rpy="0 0 0" xyz="0 0 0" />
    <parent link="right_arm_link7" />
    <child link="right_camera" />
  </joint>
  <link name="right_camera">
    <inertial>
      <origin rpy="0 0 0" xyz="-0.0621229724155358 -0.0628379837355285 -0.00140310958315455" />
      <mass value="0.0492751941348016" />
      <inertia ixx="3.66069470547417E-05" ixy="-3.55284385731841E-07" ixz="3.8533182318026E-07" iyy="3.08593710158624E-05" iyz="-3.07292981503681E-07" izz="8.80145863410975E-06" />
    </inertial>
    <visual>
      <origin rpy="0 0 0" xyz="0 0 0" />
      <geometry>
        <mesh filename="assets/embodiments/galbot-one-golf/urdf/meshes/visual/camera/d405_camera/right_wrist_d405_camera/obj/right_wrist_d405_camera.obj" />
      </geometry>
      <material name="material_right_wrist_d405_camera">
        <color rgba="0.7 0.7 0.7 1.0" />
      </material>
    </visual>
  </link>
  <joint name="left_gripper_joint" type="fixed">
    <origin rpy="1.5707963267948966 0 0" xyz="0 0 0" />
    <parent link="left_arm_end_effector_mount_link" />
    <child link="left_gripper_flange_link" />
  </joint>
  <link name="left_gripper_flange_link">
    <inertial>
      <origin rpy="0 0 0" xyz="0.0030662 -1.4019E-18 3.383E-18" />
      <mass value="0.031005" />
      <inertia ixx="2.2585E-05" ixy="-2.0366E-21" ixz="-3.7461E-22" iyy="1.141E-05" iyz="-7.8518E-23" izz="1.141E-05" />
    </inertial>
    <visual>
      <geometry>
        <mesh filename="assets/embodiments/galbot-one-golf/urdf/meshes/visual/gripper/galbot_gripper1/flange_link.obj" />
      </geometry>
    </visual>
  </link>
  <joint name="left_gripper_base_joint" type="fixed">
    <origin rpy="0 0 0" xyz="0.0065 0 0" />
    <parent link="left_gripper_flange_link" />
    <child link="left_gripper_base_link" />
    <axis xyz="0 0 0" />
  </joint>
  <link name="left_gripper_base_link">
    <inertial>
      <origin rpy="0 0 0" xyz="0.037051 -6.4001E-05 6.4706E-05" />
      <mass value="0.061747" />
      <inertia ixx="2.5813E-05" ixy="4.7224E-08" ixz="-3.9403E-11" iyy="7.2859E-05" iyz="-2.962E-10" izz="5.7173E-05" />
    </inertial>
    <visual>
      <geometry>
        <mesh filename="assets/embodiments/galbot-one-golf/urdf/meshes/visual/gripper/galbot_gripper1/base_link.obj" />
      </geometry>
    </visual>
  </link>
  <link name="left_gripper_l_knuckle_link">
    <inertial>
      <origin rpy="0 0 0" xyz="0.024101 0 0" />
      <mass value="0.0070682" />
      <inertia ixx="9.2131e-08" ixy="0" ixz="0" iyy="1.559e-06" iyz="0" izz="1.4931e-06" />
    </inertial>
    <visual>
      <geometry>
        <mesh filename="assets/embodiments/galbot-one-golf/urdf/meshes/visual/gripper/galbot_gripper1/l_link_1.obj" />
      </geometry>
    </visual>
  </link>
  <link name="left_gripper_l_inner_knuckle_link">
    <inertial>
      <origin rpy="0 0 0" xyz="0.023769 0 0" />
      <mass value="0.007802" />
      <inertia ixx="1.044e-07" ixy="0" ixz="0" iyy="1.6385e-06" iyz="0" izz="1.566e-06" />
    </inertial>
    <visual>
      <geometry>
        <mesh filename="assets/embodiments/galbot-one-golf/urdf/meshes/visual/gripper/galbot_gripper1/l_link_2.obj" />
      </geometry>
    </visual>
  </link>
  <joint name="left_gripper_l_inner_knuckle_joint" type="revolute">
    <parent link="left_gripper_base_link" />
    <child link="left_gripper_l_inner_knuckle_link" />
    <origin rpy="1.5707963267948966 1.2465 0" xyz="0.079 0 -0.026" />
    <axis xyz="0 0 1" />
    <limit effort="1000" lower="-3.13" upper="3.13" velocity="2.0" />
  </joint>
  <link name="left_gripper_l_finger_link">
    <inertial>
      <origin rpy="0 0 0" xyz="0.016809 0.0019094 0" />
      <mass value="0.1" />
      <inertia ixx="3.4734e-06" ixy="0" ixz="0" iyy="1.1619e-05" iyz="0" izz="9.563e-06" />
    </inertial>
    <visual>
      <geometry>
        <mesh filename="assets/embodiments/galbot-one-golf/urdf/meshes/visual/gripper/galbot_gripper1/l_link_3_zhitao.obj" />
      </geometry>
    </visual>
    <collision>
      <origin rpy="0 0 0" xyz="0 0 0" />
      <geometry>
        <mesh filename="assets/embodiments/galbot-one-golf/urdf/meshes/collision/gripper/galbot_gripper1/convex_decomposition/l_link_3_zhitao_convex_decomposition/l_link_3_zhitao_convex_decomposition_0.stl" />
      </geometry>
    </collision>
    <collision>
      <origin rpy="0 0 0" xyz="0 0 0" />
      <geometry>
        <mesh filename="assets/embodiments/galbot-one-golf/urdf/meshes/collision/gripper/galbot_gripper1/convex_decomposition/l_link_3_zhitao_convex_decomposition/l_link_3_zhitao_convex_decomposition_1.stl" />
      </geometry>
    </collision>
    <collision>
      <origin rpy="0 0 0" xyz="0 0 0" />
      <geometry>
        <mesh filename="assets/embodiments/galbot-one-golf/urdf/meshes/collision/gripper/galbot_gripper1/convex_decomposition/l_link_3_zhitao_convex_decomposition/l_link_3_zhitao_convex_decomposition_2.stl" />
      </geometry>
    </collision>
    <collision>
      <origin rpy="0 0 0" xyz="0 0 0" />
      <geometry>
        <mesh filename="assets/embodiments/galbot-one-golf/urdf/meshes/collision/gripper/galbot_gripper1/convex_decomposition/l_link_3_zhitao_convex_decomposition/l_link_3_zhitao_convex_decomposition_3.stl" />
      </geometry>
    </collision>
    <collision>
      <origin rpy="0 0 0" xyz="0 0 0" />
      <geometry>
        <mesh filename="assets/embodiments/galbot-one-golf/urdf/meshes/collision/gripper/galbot_gripper1/convex_decomposition/l_link_3_zhitao_convex_decomposition/l_link_3_zhitao_convex_decomposition_4.stl" />
      </geometry>
    </collision>
    <collision>
      <origin rpy="0 0 0" xyz="0 0 0" />
      <geometry>
        <mesh filename="assets/embodiments/galbot-one-golf/urdf/meshes/collision/gripper/galbot_gripper1/convex_decomposition/l_link_3_zhitao_convex_decomposition/l_link_3_zhitao_convex_decomposition_5.stl" />
      </geometry>
    </collision>
  </link>
  <joint name="left_gripper_l_finger_joint" type="revolute">
    <parent link="left_gripper_l_inner_knuckle_link" />
    <child link="left_gripper_l_finger_link" />
    <origin rpy="0 0 1.2465" xyz="0.045 0 0" />
    <axis xyz="0 0 1" />
    <limit effort="1000" lower="-3.13" upper="3.13" velocity="2.0" />
  </joint>
  <link name="left_gripper_r_knuckle_link">
    <inertial>
      <origin rpy="0 0 0" xyz="0.024101 0 0" />
      <mass value="0.0070682" />
      <inertia ixx="9.2131e-08" ixy="0" ixz="0" iyy="1.559e-06" iyz="0" izz="1.4931e-06" />
    </inertial>
    <visual>
      <geometry>
        <mesh filename="assets/embodiments/galbot-one-golf/urdf/meshes/visual/gripper/galbot_gripper1/r_link_1.obj" />
      </geometry>
    </visual>
  </link>
  <link name="left_gripper_r_inner_knuckle_link">
    <inertial>
      <origin rpy="0 0 0" xyz="0.023769 0 0" />
      <mass value="0.007802" />
      <inertia ixx="1.044e-07" ixy="0" ixz="0" iyy="1.6385e-06" iyz="0" izz="1.566e-06" />
    </inertial>
    <visual>
      <geometry>
        <mesh filename="assets/embodiments/galbot-one-golf/urdf/meshes/visual/gripper/galbot_gripper1/r_link_2.obj" />
      </geometry>
    </visual>
  </link>
  <joint name="left_gripper_r_inner_knuckle_joint" type="revolute">
    <parent link="left_gripper_base_link" />
    <child link="left_gripper_r_inner_knuckle_link" />
    <origin rpy="1.5707963267948966 -1.2465 0" xyz="0.079 0 0.026" />
    <axis xyz="0 0 1" />
    <limit effort="1000" lower="-3.13" upper="3.13" velocity="2.0" />
  </joint>
  <link name="left_gripper_r_finger_link">
    <inertial>
      <origin rpy="0 0 0" xyz="0.016809 -0.0019094 0" />
      <mass value="0.1" />
      <inertia ixx="3.4734e-06" ixy="0" ixz="0" iyy="1.1619e-05" iyz="0" izz="9.563e-06" />
    </inertial>
    <visual>
      <geometry>
        <mesh filename="assets/embodiments/galbot-one-golf/urdf/meshes/visual/gripper/galbot_gripper1/r_link_3_zhitao.obj" />
      </geometry>
    </visual>
    <collision>
      <origin rpy="0 0 0" xyz="0 0 0" />
      <geometry>
        <mesh filename="assets/embodiments/galbot-one-golf/urdf/meshes/collision/gripper/galbot_gripper1/convex_decomposition/r_link_3_zhitao_convex_decomposition/r_link_3_zhitao_convex_decomposition_0.stl" />
      </geometry>
    </collision>
    <collision>
      <origin rpy="0 0 0" xyz="0 0 0" />
      <geometry>
        <mesh filename="assets/embodiments/galbot-one-golf/urdf/meshes/collision/gripper/galbot_gripper1/convex_decomposition/r_link_3_zhitao_convex_decomposition/r_link_3_zhitao_convex_decomposition_1.stl" />
      </geometry>
    </collision>
    <collision>
      <origin rpy="0 0 0" xyz="0 0 0" />
      <geometry>
        <mesh filename="assets/embodiments/galbot-one-golf/urdf/meshes/collision/gripper/galbot_gripper1/convex_decomposition/r_link_3_zhitao_convex_decomposition/r_link_3_zhitao_convex_decomposition_2.stl" />
      </geometry>
    </collision>
    <collision>
      <origin rpy="0 0 0" xyz="0 0 0" />
      <geometry>
        <mesh filename="assets/embodiments/galbot-one-golf/urdf/meshes/collision/gripper/galbot_gripper1/convex_decomposition/r_link_3_zhitao_convex_decomposition/r_link_3_zhitao_convex_decomposition_3.stl" />
      </geometry>
    </collision>
  </link>
  <joint name="left_gripper_r_finger_joint" type="revolute">
    <parent link="left_gripper_r_inner_knuckle_link" />
    <child link="left_gripper_r_finger_link" />
    <origin rpy="0 0 -1.2465" xyz="0.045 0 0" />
    <axis xyz="0 0 1" />
    <limit effort="1000" lower="-3.13" upper="3.13" velocity="2.0" />
  </joint>
  <joint name="left_gripper_r_knuckle_joint" type="revolute">
    <parent link="left_gripper_base_link" />
    <child link="left_gripper_r_knuckle_link" />
    <origin rpy="1.5707963267948966 -1.2465 0" xyz="0.0745 0 0.0385" />
    <axis xyz="0 0 -1" />
    <limit effort="1000" lower="0.0" upper="1.703" velocity="20.0" />
  </joint>
  <joint name="left_gripper_l_knuckle_joint" type="revolute">
    <parent link="left_gripper_base_link" />
    <child link="left_gripper_l_knuckle_link" />
    <origin rpy="1.5707963267948966 1.2465 0" xyz="0.0745 0 -0.0385" />
    <axis xyz="0 0 1" />
    <limit effort="1000" lower="-3.13" upper="3.13" velocity="20.0" />
  </joint>
  <link name="left_gripper_tcp_link" />
  <joint name="left_gripper_tcp_joint" type="fixed">
    <parent link="left_gripper_base_link" />
    <child link="left_gripper_tcp_link" />
    <origin rpy="-1.5707963267948966 0 0" xyz="0.1470480202320212 0 0" />
  </joint>
  <joint name="left_joint" type="fixed">
    <origin rpy="0 0 0" xyz="0 0 0" />
    <parent link="left_arm_link7" />
    <child link="left_camera" />
  </joint>
  <link name="left_camera">
    <inertial>
      <origin rpy="0 0 0" xyz="-0.0687164275307753 0.00742418594708705 -0.0656976688947199" />
      <mass value="0.0533223543172611" />
      <inertia ixx="2.57961610647567E-05" ixy="-4.79475020826079E-07" ixz="-1.78893716134214E-06" iyy="1.37594261317448E-05" iyz="2.73965367892125E-07" izz="1.70502507719673E-05" />
    </inertial>
    <visual>
      <origin rpy="0 0 0" xyz="0 0 0" />
      <geometry>
        <mesh filename="assets/embodiments/galbot-one-golf/urdf/meshes/visual/camera/d405_camera/left_wrist_d405_camera/obj/left_wrist_d405_camera.obj" />
      </geometry>
      <material name="material_right_wrist_d405_camera">
        <color rgba="0.7 0.7 0.7 1.0" />
      </material>
    </visual>
  </link>
</robot>